Workbook

Sheet Reglas
B1: Árbol de tecnologías v0.2 — 203 propuestas en 12 ramas con columna vertebral
B2: Todo es una propuesta para corregir. Las 36 tecnologías marcadas como 'Tuya' conservan tus efectos; los nombres, prerrequisitos y el resto son míos.
B4: Parámetros (celdas amarillas: se pueden cambiar)
B5: Costo por nivel (puntos de tecnología) | C5: 20 | D5: Tuyo: nivel 1 = 20, nivel 2 = 40 … nivel 5 = 100. El costo de cada tecnología es Nivel × este valor.
B6: Mín. de tecnologías de nivel 1 para investigar una de nivel 2 | C6: 3 | D6: Propuesta mía. Cuentan tecnologías de cualquier rama, vertebrales u opcionales.
B7: Mín. de tecnologías de nivel 2 para investigar una de nivel 3 | C7: 5 | D7: Propuesta mía.
B8: Mín. de tecnologías de nivel 3 para investigar una de nivel 4 | C8: 6 | D8: Propuesta mía.
B9: Mín. de tecnologías de nivel 4 para investigar una de nivel 5 | C9: 6 | D9: Propuesta mía.
B11: Cómo funciona el árbol
B12: Hay 12 ramas. Cada rama tiene una COLUMNA VERTEBRAL (de 6 a 7 tecnologías, con al menos una por nivel y una sola de nivel 5) y tecnologías OPCIONALES (especializaciones y extras).
B13: Para investigar cualquier tecnología de nivel 5 de una rama hay que haber completado antes la columna vertebral de esa rama hasta el nivel 4. Las opcionales no cuentan para completar la columna.
B14: Además, para investigar una tecnología de nivel n hace falta el mínimo de tecnologías del nivel n−1 indicado arriba (de cualquier rama), y todos sus prerrequisitos directos (máximo 2, de nivel menor).
B15: Un edificio se desbloquea con su tecnología de nivel 1. Las de niveles 2 a 5 lo mejoran o lo especializan ('Esp.'). Las tecnologías de zona desbloquean los niveles 2 y 3 de las zonas especializadas (nivel 2 con tecnología de nivel 2; nivel 3 con la de nivel 4).
B16: Tipo = Civil, Construcción o Militar. Cuartel, Fortificación y las máquinas de asedio se marcan como Militar; los demás edificios, como Construcción.
B18: Victoria tecnológica (5 tecnologías de nivel 5)
B19: Con 5 tecnologías de nivel 5 de RAMAS DISTINTAS: camino más barato | C19: 1700 | D19: Calculado por script con los mínimos 3 / 5 / 6 / 6 y con los 9 edificios básicos ya desarrollados (36 tecnologías contando esas 9). Entre las combinaciones de 5 ramas, el costo va de 1700 a 2040.
B20: Si bastara con CUALQUIER 5 de nivel 5 (aunque sean de la misma rama) | C20: 1500 | D20: Estimación: se lograría con solo 2 ramas (Logística y Armas y unidades), por eso recomiendo exigir ramas distintas.
B21: Costo de completar una sola columna vertebral (promedio) | C21: 363 | D21: Entre 280 y 440 según la rama, descontando las tecnologías iniciales (ver hoja 'Ramas').
B23: Columnas de la hoja 'Tecnologías'
B24: Columna | C24: Vertebral = obligatoria para completar la rama y poder llegar al nivel 5. Opcional = especialización o extra que no cuenta para completarla.
B25: Valoración (1–5) | C25: 5 = muy buena (clara, divertida y bien balanceada); 4 = buena; 3 = aceptable o situacional; 2 = débil, redundante o arriesgada; 1 = problemática. Es mi opinión, para discutir.
B26: Riesgo de balance | C26: Bajo / Medio / Alto: qué tan probable es que desbalancee el juego. Se mide con el simulador, no a ojo.
B27: Origen | C27: 'Tuya' = viene de tu lista (36 tecnologías, con tus efectos). 'Mía' = propuesta nueva.
B28: Subrama | C28: La agrupación temática anterior (30 grupos), útil para filtrar por tema. La Rama (12) es la que cuenta para el árbol.
B29: Esp. | C29: Especialización de un edificio: variante que eliges para ese edificio, distinta de la mejora general.
B31: Cambios respecto a la versión anterior
B32: • Los 9 edificios básicos (Almacenes, Caminos, Hospitales, Cuarteles, Fortificaciones, Bibliotecas, Molinos, Talleres y Mercados) vienen ya desarrollados al inicio (columna Inicial = Sí, costo 0). Cuentan para los mínimos del nivel 1.
B33: • La investigación ya no es instantánea: cada tecnología avanza cada paso hasta la capacidad de los científicos asignados a investigar (2 de ciencia por científico, más el bono de la zona de tecnología). Un científico genera 2 de ciencia o usa 2 para investigar, no ambas cosas.
B34: • Se eliminó 'Pacificación' (contradecía el sistema de capturas) y se reemplazaron 'Asedio' y 'Catapultas' por 6 tecnologías de máquinas de asedio (arietes y lanzapiedras, con 3 niveles cada una).
B35: • 'Gremio mercantil' pasó a llamarse 'Gran compañía' para no confundirse con 'Gremios mercantiles' (zona comercial nivel 3).
B36: • Varios prerrequisitos de las tecnologías vertebrales se cambiaron para que cada columna dependa solo de sí misma.
B38: Supuestos y dudas abiertas
B39: • Los bonos de 'Esp.' de Almacén por nivel (+10, +20, +30, +100) se asumen NO acumulables: cada uno reemplaza al anterior.
B40: • Se asume que un mismo edificio tiene una sola especialización a la vez.
B41: • 'Camino militar I' dice +1 de iniciativa. Como el número menor actúa primero, ¿es más lento o más rápido? Se propone −1 (más rápido).
B42: • Hospital imperial (+2 de vida a todos) es una tecnología tuya y es el nivel 5 de la columna de Sanidad: obliga a quien quiera esa rama a tomarla. Está marcada con riesgo alto.
B43: • Varias tecnologías usan mecánicas aún no definidas: zonas riesgosas, vender recursos (Exportaciones), mercenarios, rendiciones por intimidación. Decidir si se quieren.
B44: • El mínimo de tecnologías del nivel anterior cuenta tecnologías de cualquier rama. Se puede exigir que sean del mismo tipo.

Sheet Tecnologías
A1: ID | B1: Nombre | C1: Nivel | D1: Costo | E1: Tipo | F1: Rama | G1: Columna | H1: Subrama | I1: Categoría de efecto | J1: Efecto | K1: Prerrequisitos directos | L1: Mín. del nivel anterior | M1: Origen | N1: Valoración (1–5) | O1: Riesgo de balance | P1: Comentario | Q1: Inicial
A2: T001 | B2: Arado | C2: 1 | D2: =IF(Q2="Sí",0,C2*Reglas!$C$5) | E2: Civil | F2: Agricultura | G2: Vertebral | H2: Agricultura | I2: Comida | J2: +1 de comida por agricultor. | K2: — | L2: =IF(C2=1,0,CHOOSE(C2-1,Reglas!$C$6,Reglas!$C$7,Reglas!$C$8,Reglas!$C$9)) | M2: Mía | N2: 5 | O2: Bajo | P2: Mejora clara y barata; sin ella, la agricultura se queda atrás.
A3: T002 | B3: Riego | C3: 2 | D3: =IF(Q3="Sí",0,C3*Reglas!$C$5) | E3: Civil | F3: Agricultura | G3: Vertebral | H3: Zonas | I3: Zona especializada | J3: Desbloquea la zona de agricultura nivel 2 (+8 de comida de zona). | K3: Arado (T001) | L3: =IF(C3=1,0,CHOOSE(C3-1,Reglas!$C$6,Reglas!$C$7,Reglas!$C$8,Reglas!$C$9)) | M3: Mía | N3: 4 | O3: Bajo | P3: Pasar del nivel 1 al 2 vale +4 de comida por 40 de tecnología: rentable pronto.
A4: T003 | B4: Huertos familiares | C4: 2 | D4: =IF(Q4="Sí",0,C4*Reglas!$C$5) | E4: Civil | F4: Agricultura | G4: Vertebral | H4: Agricultura | I4: Comida | J4: +1 de comida por poblador normal. | K4: Arado (T001) | L4: =IF(C4=1,0,CHOOSE(C4-1,Reglas!$C$6,Reglas!$C$7,Reglas!$C$8,Reglas!$C$9)) | M4: Mía | N4: 4 | O4: Bajo | P4: Beneficia a las zonas básicas, que son las más comunes al inicio.
A5: T004 | B5: Abonos | C5: 3 | D5: =IF(Q5="Sí",0,C5*Reglas!$C$5) | E5: Civil | F5: Agricultura | G5: Vertebral | H5: Agricultura | I5: Comida | J5: +1 de comida por agricultor (se suma al Arado). | K5: Arado (T001); Huertos familiares (T003) | L5: =IF(C5=1,0,CHOOSE(C5-1,Reglas!$C$6,Reglas!$C$7,Reglas!$C$8,Reglas!$C$9)) | M5: Mía | N5: 4 | O5: Bajo | P5: Escala bien con zonas agrícolas especializadas.
A6: T005 | B6: Cosecha comunal | C6: 4 | D6: =IF(Q6="Sí",0,C6*Reglas!$C$5) | E6: Civil | F6: Agricultura | G6: Vertebral | H6: Zonas | I6: Zona especializada | J6: Desbloquea la zona de agricultura nivel 3 (+12 de comida de zona). | K6: Riego (T002); Abonos (T004) | L6: =IF(C6=1,0,CHOOSE(C6-1,Reglas!$C$6,Reglas!$C$7,Reglas!$C$8,Reglas!$C$9)) | M6: Mía | N6: 4 | O6: Bajo | P6: Cierra la rama de agricultura con un bono grande.
A7: T006 | B7: Granjas modelo | C7: 5 | D7: =IF(Q7="Sí",0,C7*Reglas!$C$5) | E7: Civil | F7: Agricultura | G7: Vertebral | H7: Agricultura | I7: Comida | J7: Desbloquea La Huerta Infinita, la maravilla de Agricultura (única en la partida): +1 de comida por agricultor mientras controles su zona. Solo se puede investigar si nadie la ha construido. | K7: Cosecha comunal (T005) | L7: =IF(C7=1,0,CHOOSE(C7-1,Reglas!$C$6,Reglas!$C$7,Reglas!$C$8,Reglas!$C$9)) | M7: Mía | N7: 3 | O7: Bajo | P7: Por sí sola no da su efecto: lo da la maravilla. Si otro la termina antes, pierdes la obra y recuperas la mitad de la producción, pero conservas la tecnología (cuenta para la victoria tecnológica).
A8: T007 | B8: Molinos | C8: 1 | D8: =IF(Q8="Sí",0,C8*Reglas!$C$5) | E8: Construcción | F8: Agricultura | G8: Opcional | H8: Molino | I8: Desbloqueo de edificio | J8: Permite construir el Molino: +1 de comida por trabajador. | K8: — | L8: =IF(C8=1,0,CHOOSE(C8-1,Reglas!$C$6,Reglas!$C$7,Reglas!$C$8,Reglas!$C$9)) | M8: Tuya | N8: 5 | O8: Bajo | P8: Mejora directa de la comida. Barata de entender y rentable pronto. | Q8: Sí
A9: T008 | B9: Molino de piedra | C9: 2 | D9: =IF(Q9="Sí",0,C9*Reglas!$C$5) | E9: Construcción | F9: Agricultura | G9: Opcional | H9: Molino | I9: Mejora de edificio | J9: El Molino da +2 de comida por trabajador (reemplaza al +1). | K9: Molinos (T007) | L9: =IF(C9=1,0,CHOOSE(C9-1,Reglas!$C$6,Reglas!$C$7,Reglas!$C$8,Reglas!$C$9)) | M9: Mía | N9: 4 | O9: Bajo | P9: Escala bien con el número de trabajadores (Andamios, Grúas).
A10: T009 | B10: Despensas | C10: 2 | D10: =IF(Q10="Sí",0,C10*Reglas!$C$5) | E10: Civil | F10: Agricultura | G10: Opcional | H10: Agricultura | I10: Comida | J10: La muerte por hambre llega a las 3 rondas en vez de 2. | K10: Arado (T001) | L10: =IF(C10=1,0,CHOOSE(C10-1,Reglas!$C$6,Reglas!$C$7,Reglas!$C$8,Reglas!$C$9)) | M10: Mía | N10: 3 | O10: Bajo | P10: Suaviza un castigo duro. Útil para quien se expande rápido y arriesga.
A11: T010 | B11: Pastoreo | C11: 2 | D11: =IF(Q11="Sí",0,C11*Reglas!$C$5) | E11: Civil | F11: Agricultura | G11: Opcional | H11: Terreno y eventos | I11: Terreno | J11: En Praderas, agricultores y pobladores producen +1 de comida adicional. | K11: Arado (T001) | L11: =IF(C11=1,0,CHOOSE(C11-1,Reglas!$C$6,Reglas!$C$7,Reglas!$C$8,Reglas!$C$9)) | M11: Mía | N11: 3 | O11: Medio | P11: Sumada al bono natural de las Praderas, agricultores y pobladores rinden +2 de comida extra. Mismo riesgo: premia al que parte con Praderas.
A12: T011 | B12: Molino-granero | C12: 3 | D12: =IF(Q12="Sí",0,C12*Reglas!$C$5) | E12: Construcción | F12: Agricultura | G12: Opcional | H12: Molino | I12: Especialización de edificio | J12: Esp.: además, el Molino da +1 de comida por cada 10 de comida almacenada en la zona (máximo +3). | K12: Molino de piedra (T008); Almacenes (T073) | L12: =IF(C12=1,0,CHOOSE(C12-1,Reglas!$C$6,Reglas!$C$7,Reglas!$C$8,Reglas!$C$9)) | M12: Mía | N12: 3 | O12: Bajo | P12: Une Molino y Almacén. Solo rinde si ahorras comida, lo que choca con crecer.
A13: T012 | B13: Ganadería | C13: 3 | D13: =IF(Q13="Sí",0,C13*Reglas!$C$5) | E13: Civil | F13: Agricultura | G13: Opcional | H13: Agricultura | I13: Comida | J13: Cada zona de agricultura gana +2 de comida por nivel de zona. | K13: Huertos familiares (T003) | L13: =IF(C13=1,0,CHOOSE(C13-1,Reglas!$C$6,Reglas!$C$7,Reglas!$C$8,Reglas!$C$9)) | M13: Mía | N13: 3 | O13: Medio | P13: Premia la especialización, pero 6 de comida extra en nivel 3 pesa mucho.
A14: T013 | B14: Semillas resistentes | C14: 3 | D14: =IF(Q14="Sí",0,C14*Reglas!$C$5) | E14: Civil | F14: Agricultura | G14: Opcional | H14: Agricultura | I14: Comida | J14: Los eventos negativos que reducen la comida afectan un 50% menos. | K14: Arado (T001) | L14: =IF(C14=1,0,CHOOSE(C14-1,Reglas!$C$6,Reglas!$C$7,Reglas!$C$8,Reglas!$C$9)) | M14: Mía | N14: 3 | O14: Bajo | P14: Buena como seguro, pero depende de qué eventos existan.
A15: T014 | B15: Molino hidráulico | C15: 4 | D15: =IF(Q15="Sí",0,C15*Reglas!$C$5) | E15: Construcción | F15: Agricultura | G15: Opcional | H15: Molino | I15: Mejora de edificio | J15: El Molino da +3 de comida por trabajador (+1 más si la zona es de Ríos). | K15: Molino-granero (T011) | L15: =IF(C15=1,0,CHOOSE(C15-1,Reglas!$C$6,Reglas!$C$7,Reglas!$C$8,Reglas!$C$9)) | M15: Mía | N15: 4 | O15: Medio | P15: Buena sinergia con el terreno. Evita que los Ríos sean solo para arqueros y comercio.
A16: T015 | B16: Irrigación avanzada | C16: 4 | D16: =IF(Q16="Sí",0,C16*Reglas!$C$5) | E16: Civil | F16: Agricultura | G16: Opcional | H16: Agricultura | I16: Comida | J16: +1 de comida por poblador normal (se suma a Huertos familiares). | K16: Abonos (T004) | L16: =IF(C16=1,0,CHOOSE(C16-1,Reglas!$C$6,Reglas!$C$7,Reglas!$C$8,Reglas!$C$9)) | M16: Mía | N16: 4 | O16: Bajo | P16: Bono continuo para zonas básicas.
A17: T016 | B17: Gran molino | C17: 5 | D17: =IF(Q17="Sí",0,C17*Reglas!$C$5) | E17: Construcción | F17: Agricultura | G17: Opcional | H17: Molino | I17: Mejora de edificio | J17: El Molino da +5 de comida por trabajador. | K17: Molino hidráulico (T014) | L17: =IF(C17=1,0,CHOOSE(C17-1,Reglas!$C$6,Reglas!$C$7,Reglas!$C$8,Reglas!$C$9)) | M17: Mía | N17: 3 | O17: Alto | P17: Con 4 trabajadores son +20 de comida por paso, más que una zona de agricultura de nivel 3. Revisar con el simulador.
A18: T017 | B18: Revolución agrícola | C18: 5 | D18: =IF(Q18="Sí",0,C18*Reglas!$C$5) | E18: Civil | F18: Agricultura | G18: Opcional | H18: Agricultura | I18: Comida | J18: Las zonas de agricultura nivel 3 generan +6 de comida adicionales. | K18: Cosecha comunal (T005); Ganadería (T012) | L18: =IF(C18=1,0,CHOOSE(C18-1,Reglas!$C$6,Reglas!$C$7,Reglas!$C$8,Reglas!$C$9)) | M18: Mía | N18: 3 | O18: Medio | P18: Fuerte, pero muy específica: solo sirve con zonas de nivel 3.
A19: T018 | B19: Herramientas | C19: 1 | D19: =IF(Q19="Sí",0,C19*Reglas!$C$5) | E19: Civil | F19: Producción | G19: Vertebral | H19: Producción | I19: Producción | J19: +1 de producción por ingeniero. | K19: — | L19: =IF(C19=1,0,CHOOSE(C19-1,Reglas!$C$6,Reglas!$C$7,Reglas!$C$8,Reglas!$C$9)) | M19: Mía | N19: 5 | O19: Bajo | P19: Mejora clara y barata; base para el plan de edificios.
A20: T019 | B20: Ingeniería básica | C20: 2 | D20: =IF(Q20="Sí",0,C20*Reglas!$C$5) | E20: Civil | F20: Producción | G20: Vertebral | H20: Zonas | I20: Zona especializada | J20: Desbloquea la zona de producción nivel 2 (+8 de producción de zona). | K20: Herramientas (T018) | L20: =IF(C20=1,0,CHOOSE(C20-1,Reglas!$C$6,Reglas!$C$7,Reglas!$C$8,Reglas!$C$9)) | M20: Mía | N20: 4 | O20: Bajo | P20: Buen salto para el plan de edificios.
... A24: T023 | B24: Maquinaria | C24: 5 | D24: =IF(Q24="Sí",0,C24*Reglas!$C$5) | E24: Civil | F24: Producción | G24: Vertebral | H24: Producción | I24: Producción | J24: Desbloquea La Gran Fragua, la maravilla de Producción (única en la partida): +1 de producción por ingeniero mientras controles su zona. Solo se puede investigar si nadie la ha construido. | K24: Ingeniería avanzada (T022) | L24: =IF(C24=1,0,CHOOSE(C24-1,Reglas!$C$6,Reglas!$C$7,Reglas!$C$8,Reglas!$C$9)) | M24: Mía | N24: 3 | O24: Medio | P24: Por sí sola no da su efecto: lo da la maravilla. Si otro la termina antes, pierdes la obra y recuperas la mitad de la producción, pero conservas la tecnología (cuenta para la victoria tecnológica).
A25: T024 | B25: Talleres | C25: 1 | D25: =IF(Q25="Sí",0,C25*Reglas!$C$5) | E25: Construcción | F25: Producción | G25: Opcional | H25: Taller | I25: Desbloqueo de edificio | J25: Permite construir el Taller: +1 de producción por trabajador. | K25: — | L25: =IF(C25=1,0,CHOOSE(C25-1,Reglas!$C$6,Reglas!$C$7,Reglas!$C$8,Reglas!$C$9)) | M25: Tuya | N25: 5 | O25: Bajo | P25: Mejora directa de producción; base para armas y edificios. | Q25: Sí
A26: T025 | B26: Taller de herrería | C26: 2 | D26: =IF(Q26="Sí",0,C26*Reglas!$C$5) | E26: Construcción | F26: Producción | G26: Opcional | H26: Taller | I26: Mejora de edificio | J26: El Taller da +2 de producción por trabajador (reemplaza al +1). | K26: Talleres (T024) | L26: =IF(C26=1,0,CHOOSE(C26-1,Reglas!$C$6,Reglas!$C$7,Reglas!$C$8,Reglas!$C$9)) | M26: Mía | N26: 4 | O26: Bajo | P26: Escala bien con los trabajadores extra.
A27: T026 | B27: Aprendices | C27: 2 | D27: =IF(Q27="Sí",0,C27*Reglas!$C$5) | E27: Civil | F27: Producción | G27: Opcional | H27: Producción | I27: Producción | J27: Especializar civiles cuesta 0 de producción en zonas con Taller. | K27: Herramientas (T018); Talleres (T024) | L27: =IF(C27=1,0,CHOOSE(C27-1,Reglas!$C$6,Reglas!$C$7,Reglas!$C$8,Reglas!$C$9)) | M27: Mía | N27: 3 | O27: Medio | P27: Fomenta tener Taller en cada zona; puede volver trivial el costo de especializar.
A28: T027 | B28: Terrazas | C28: 2 | D28: =IF(Q28="Sí",0,C28*Reglas!$C$5) | E28: Civil | F28: Producción | G28: Opcional | H28: Terreno y eventos | I28: Terreno | J28: En Montañas, ingenieros y pobladores producen +1 de producción adicional. | K28: Herramientas (T018) | L28: =IF(C28=1,0,CHOOSE(C28-1,Reglas!$C$6,Reglas!$C$7,Reglas!$C$8,Reglas!$C$9)) | M28: Mía | N28: 3 | O28: Medio | P28: Sumada al bono natural de las Montañas, un ingeniero rinde +2 de producción extra en esa zona. Premia buscar el terreno, pero también inclina el mapa a favor de quien parte con Montañas.
A29: T028 | B29: Taller de armería | C29: 3 | D29: =IF(Q29="Sí",0,C29*Reglas!$C$5) | E29: Construcción | F29: Producción | G29: Opcional | H29: Taller | I29: Especialización de edificio | J29: Esp.: las armas fabricadas en este Taller cuestan 1 de producción menos. | K29: Taller de herrería (T025); Cuarteles (T158) | L29: =IF(C29=1,0,CHOOSE(C29-1,Reglas!$C$6,Reglas!$C$7,Reglas!$C$8,Reglas!$C$9)) | M29: Mía | N29: 3 | O29: Bajo | P29: Une economía y guerra. Los costos de armas (3 a 6) son bajos, así que el ahorro puede ser pequeño.
A30: T029 | B30: Taller de maquinaria | C30: 4 | D30: =IF(Q30="Sí",0,C30*Reglas!$C$5) | E30: Construcción | F30: Producción | G30: Opcional | H30: Taller | I30: Mejora de edificio | J30: El Taller da +3 de producción por trabajador. | K30: Taller de armería (T028) | L30: =IF(C30=1,0,CHOOSE(C30-1,Reglas!$C$6,Reglas!$C$7,Reglas!$C$8,Reglas!$C$9)) | M30: Mía | N30: 4 | O30: Medio | P30: Es el camino natural hacia las Maravillas.
A31: T030 | B31: Línea de ensamblaje | C31: 4 | D31: =IF(Q31="Sí",0,C31*Reglas!$C$5) | E31: Civil | F31: Producción | G31: Opcional | H31: Producción | I31: Producción | J31: Cada ingeniero que construye puede usar +1 de producción por paso (se suma a Cuadrillas de obra). | K31: Cuadrillas de obra (T092); Minería (T021) | L31: =IF(C31=1,0,CHOOSE(C31-1,Reglas!$C$6,Reglas!$C$7,Reglas!$C$8,Reglas!$C$9)) | M31: Mía | N31: 3 | O31: Medio | P31: Fuerte para los planes de edificios y Maravillas.
A32: T031 | B32: Gran manufactura | C32: 5 | D32: =IF(Q32="Sí",0,C32*Reglas!$C$5) | E32: Construcción | F32: Producción | G32: Opcional | H32: Taller | I32: Mejora de edificio | J32: El Taller da +5 de producción por trabajador. | K32: Taller de maquinaria (T029) | L32: =IF(C32=1,0,CHOOSE(C32-1,Reglas!$C$6,Reglas!$C$7,Reglas!$C$8,Reglas!$C$9)) | M32: Mía | N32: 3 | O32: Alto | P32: Con 4 trabajadores son +20 de producción por paso: una Maravilla cada 25 pasos solo con este edificio. Vigilar.
A33: T032 | B33: Moneda | C33: 1 | D33: =IF(Q33="Sí",0,C33*Reglas!$C$5) | E33: Civil | F33: Comercio | G33: Vertebral | H33: Comercio | I33: Oro | J33: +1 de oro por comerciante. | K33: — | L33: =IF(C33=1,0,CHOOSE(C33-1,Reglas!$C$6,Reglas!$C$7,Reglas!$C$8,Reglas!$C$9)) | M33: Mía | N33: 5 | O33: Bajo | P33: Mejora clara y barata; hace viable la zona comercial.
A34: T033 | B34: Rutas comerciales | C34: 2 | D34: =IF(Q34="Sí",0,C34*Reglas!$C$5) | E34: Civil | F34: Comercio | G34: Vertebral | H34: Zonas | I34: Zona especializada | J34: Desbloquea la zona comercial nivel 2 (+8 de oro de zona). | K34: Moneda (T032) | L34: =IF(C34=1,0,CHOOSE(C34-1,Reglas!$C$6,Reglas!$C$7,Reglas!$C$8,Reglas!$C$9)) | M34: Mía | N34: 4 | O34: Bajo | P34: Pasa de 4 a 8 de oro de zona; muy buena inversión.
A35: T034 | B35: Caravanas | C35: 2 | D35: =IF(Q35="Sí",0,C35*Reglas!$C$5) | E35: Civil | F35: Comercio | G35: Vertebral | H35: Comercio | I35: Oro | J35: Los primeros 5 de comida o producción que muevas cada paso no pagan logística. | K35: Moneda (T032) | L35: =IF(C35=1,0,CHOOSE(C35-1,Reglas!$C$6,Reglas!$C$7,Reglas!$C$8,Reglas!$C$9)) | M35: Mía | N35: 4 | O35: Bajo | P35: Hace sentir menos el costo del oro al inicio.
A36: T035 | B36: Contabilidad | C36: 3 | D36: =IF(Q36="Sí",0,C36*Reglas!$C$5) | E36: Civil | F36: Comercio | G36: Vertebral | H36: Comercio | I36: Oro | J36: Comprar un recurso faltante cuesta 2 de oro (en vez de 3). | K36: Moneda (T032); Caravanas (T034) | L36: =IF(C36=1,0,CHOOSE(C36-1,Reglas!$C$6,Reglas!$C$7,Reglas!$C$8,Reglas!$C$9)) | M36: Mía | N36: 4 | O36: Bajo | P36: Reduce el castigo de las escaseces.
A37: T036 | B37: Gremios mercantiles | C37: 4 | D37: =IF(Q37="Sí",0,C37*Reglas!$C$5) | E37: Civil | F37: Comercio | G37: Vertebral | H37: Zonas | I37: Zona especializada | J37: Desbloquea la zona comercial nivel 3 (+12 de oro de zona). | K37: Rutas comerciales (T033); Contabilidad (T035) | L37: =IF(C37=1,0,CHOOSE(C37-1,Reglas!$C$6,Reglas!$C$7,Reglas!$C$8,Reglas!$C$9)) | M37: Mía | N37: 4 | O37: Bajo | P37: Empuja hacia los 1000 de oro.
A38: T037 | B38: Gran compañía | C38: 5 | D38: =IF(Q38="Sí",0,C38*Reglas!$C$5) | E38: Civil | F38: Comercio | G38: Vertebral | H38: Comercio | I38: Oro | J38: Desbloquea La Lonja Dorada, la maravilla de Comercio (única en la partida): +1 de oro por comerciante mientras controles su zona. Solo se puede investigar si nadie la ha construido. | K38: Gremios mercantiles (T036) | L38: =IF(C38=1,0,CHOOSE(C38-1,Reglas!$C$6,Reglas!$C$7,Reglas!$C$8,Reglas!$C$9)) | M38: Mía | N38: 3 | O38: Bajo | P38: Por sí sola no da su efecto: lo da la maravilla. Si otro la termina antes, pierdes la obra y recuperas la mitad de la producción, pero conservas la tecnología (cuenta para la victoria tecnológica).
A39: T038 | B39: Mercados | C39: 1 | D39: =IF(Q39="Sí",0,C39*Reglas!$C$5) | E39: Construcción | F39: Comercio | G39: Opcional | H39: Mercado | I39: Desbloqueo de edificio | J39: Permite construir el Mercado: +1 de oro por trabajador. | K39: — | L39: =IF(C39=1,0,CHOOSE(C39-1,Reglas!$C$6,Reglas!$C$7,Reglas!$C$8,Reglas!$C$9)) | M39: Tuya | N39: 5 | O39: Bajo | P39: Primer ingreso de oro fuera de la zona comercial. | Q39: Sí
A40: T039 | B40: Mercado central | C40: 2 | D40: =IF(Q40="Sí",0,C40*Reglas!$C$5) | E40: Construcción | F40: Comercio | G40: Opcional | H40: Mercado | I40: Mejora de edificio | J40: El Mercado da +2 de oro por trabajador (reemplaza al +1). | K40: Mercados (T038) | L40: =IF(C40=1,0,CHOOSE(C40-1,Reglas!$C$6,Reglas!$C$7,Reglas!$C$8,Reglas!$C$9)) | M40: Mía | N40: 4 | O40: Bajo | P40: Escala bien con los trabajadores extra.
A41: T040 | B41: Impuestos | C41: 2 | D41: =IF(Q41="Sí",0,C41*Reglas!$C$5) | E41: Civil | F41: Comercio | G41: Opcional | H41: Comercio | I41: Oro | J41: +1 de oro por cada 2 zonas que controles. | K41: Moneda (T032) | L41: =IF(C41=1,0,CHOOSE(C41-1,Reglas!$C$6,Reglas!$C$7,Reglas!$C$8,Reglas!$C$9)) | M41: Mía | N41: 3 | O41: Medio | P41: Premia expandirse. Con 12 zonas serían +6 de oro: moderado.
A42: T041 | B42: Exportaciones | C42: 2 | D42: =IF(Q42="Sí",0,C42*Reglas!$C$5) | E42: Civil | F42: Comercio | G42: Opcional | H42: Comercio | I42: Oro | J42: Puedes vender 2 de comida o producción de tu almacén por 1 de oro (por orden). | K42: Moneda (T032) | L42: =IF(C42=1,0,CHOOSE(C42-1,Reglas!$C$6,Reglas!$C$7,Reglas!$C$8,Reglas!$C$9)) | M42: Mía | N42: 3 | O42: Medio | P42: Introduce la venta de recursos, que hoy no existe. Decidir si se quiere.
A43: T042 | B43: Comercio fluvial | C43: 2 | D43: =IF(Q43="Sí",0,C43*Reglas!$C$5) | E43: Civil | F43: Comercio | G43: Opcional | H43: Terreno y eventos | I43: Terreno | J43: En Ríos, los comerciantes generan +1 de oro adicional. | K43: Moneda (T032) | L43: =IF(C43=1,0,CHOOSE(C43-1,Reglas!$C$6,Reglas!$C$7,Reglas!$C$8,Reglas!$C$9)) | M43: Mía | N43: 3 | O43: Medio | P43: Hace de los Ríos el mejor lugar para comerciar (+2 de oro por comerciante). Combina con el bono de arqueros defensores del mismo terreno.
...

Sheet Ramas
B1: Las 12 ramas y su columna vertebral
B2: Costo hasta nivel 4 = lo necesario para poder investigar el nivel 5 de la rama. Costo de la columna = incluye la tecnología vertebral de nivel 5.
B4: Rama | C4: Tipo | D4: Tecnologías | E4: Vertebrales | F4: Opcionales | G4: Costo hasta nivel 4 (columna) | H4: Costo de la columna completa | I4: Valoración media | J4: Riesgo alto
B5: Agricultura | C5: Civil | D5: =COUNTIF(Tecnologías!$F$2:$F$204,B5) | E5: =COUNTIFS(Tecnologías!$F$2:$F$204,B5,Tecnologías!$G$2:$G$204,"Vertebral") | F5: =COUNTIFS(Tecnologías!$F$2:$F$204,B5,Tecnologías!$G$2:$G$204,"Opcional") | G5: =SUMIFS(Tecnologías!$D$2:$D$204,Tecnologías!$F$2:$F$204,B5,Tecnologías!$G$2:$G$204,"Vertebral",Tecnologías!$C$2:$C$204,"<=4") | H5: =SUMIFS(Tecnologías!$D$2:$D$204,Tecnologías!$F$2:$F$204,B5,Tecnologías!$G$2:$G$204,"Vertebral") | I5: =AVERAGEIF(Tecnologías!$F$2:$F$204,B5,Tecnologías!$N$2:$N$204) | J5: =COUNTIFS(Tecnologías!$F$2:$F$204,B5,Tecnologías!$O$2:$O$204,"Alto")
B6: Producción | C6: Civil | D6: =COUNTIF(Tecnologías!$F$2:$F$204,B6) | E6: =COUNTIFS(Tecnologías!$F$2:$F$204,B6,Tecnologías!$G$2:$G$204,"Vertebral") | F6: =COUNTIFS(Tecnologías!$F$2:$F$204,B6,Tecnologías!$G$2:$G$204,"Opcional") | G6: =SUMIFS(Tecnologías!$D$2:$D$204,Tecnologías!$F$2:$F$204,B6,Tecnologías!$G$2:$G$204,"Vertebral",Tecnologías!$C$2:$C$204,"<=4") | H6: =SUMIFS(Tecnologías!$D$2:$D$204,Tecnologías!$F$2:$F$204,B6,Tecnologías!$G$2:$G$204,"Vertebral") | I6: =AVERAGEIF(Tecnologías!$F$2:$F$204,B6,Tecnologías!$N$2:$N$204) | J6: =COUNTIFS(Tecnologías!$F$2:$F$204,B6,Tecnologías!$O$2:$O$204,"Alto")
B7: Comercio | C7: Civil | D7: =COUNTIF(Tecnologías!$F$2:$F$204,B7) | E7: =COUNTIFS(Tecnologías!$F$2:$F$204,B7,Tecnologías!$G$2:$G$204,"Vertebral") | F7: =COUNTIFS(Tecnologías!$F$2:$F$204,B7,Tecnologías!$G$2:$G$204,"Opcional") | G7: =SUMIFS(Tecnologías!$D$2:$D$204,Tecnologías!$F$2:$F$204,B7,Tecnologías!$G$2:$G$204,"Vertebral",Tecnologías!$C$2:$C$204,"<=4") | H7: =SUMIFS(Tecnologías!$D$2:$D$204,Tecnologías!$F$2:$F$204,B7,Tecnologías!$G$2:$G$204,"Vertebral") | I7: =AVERAGEIF(Tecnologías!$F$2:$F$204,B7,Tecnologías!$N$2:$N$204) | J7: =COUNTIFS(Tecnologías!$F$2:$F$204,B7,Tecnologías!$O$2:$O$204,"Alto")
B8: Saber | C8: Civil | D8: =COUNTIF(Tecnologías!$F$2:$F$204,B8) | E8: =COUNTIFS(Tecnologías!$F$2:$F$204,B8,Tecnologías!$G$2:$G$204,"Vertebral") | F8: =COUNTIFS(Tecnologías!$F$2:$F$204,B8,Tecnologías!$G$2:$G$204,"Opcional") | G8: =SUMIFS(Tecnologías!$D$2:$D$204,Tecnologías!$F$2:$F$204,B8,Tecnologías!$G$2:$G$204,"Vertebral",Tecnologías!$C$2:$C$204,"<=4") | H8: =SUMIFS(Tecnologías!$D$2:$D$204,Tecnologías!$F$2:$F$204,B8,Tecnologías!$G$2:$G$204,"Vertebral") | I8: =AVERAGEIF(Tecnologías!$F$2:$F$204,B8,Tecnologías!$N$2:$N$204) | J8: =COUNTIFS(Tecnologías!$F$2:$F$204,B8,Tecnologías!$O$2:$O$204,"Alto")
B9: Logística | C9: Construcción | D9: =COUNTIF(Tecnologías!$F$2:$F$204,B9) | E9: =COUNTIFS(Tecnologías!$F$2:$F$204,B9,Tecnologías!$G$2:$G$204,"Vertebral") | F9: =COUNTIFS(Tecnologías!$F$2:$F$204,B9,Tecnologías!$G$2:$G$204,"Opcional") | G9: =SUMIFS(Tecnologías!$D$2:$D$204,Tecnologías!$F$2:$F$204,B9,Tecnologías!$G$2:$G$204,"Vertebral",Tecnologías!$C$2:$C$204,"<=4") | H9: =SUMIFS(Tecnologías!$D$2:$D$204,Tecnologías!$F$2:$F$204,B9,Tecnologías!$G$2:$G$204,"Vertebral") | I9: =AVERAGEIF(Tecnologías!$F$2:$F$204,B9,Tecnologías!$N$2:$N$204) | J9: =COUNTIFS(Tecnologías!$F$2:$F$204,B9,Tecnologías!$O$2:$O$204,"Alto")
B10: Urbanismo | C10: Construcción | D10: =COUNTIF(Tecnologías!$F$2:$F$204,B10) | E10: =COUNTIFS(Tecnologías!$F$2:$F$204,B10,Tecnologías!$G$2:$G$204,"Vertebral") | F10: =COUNTIFS(Tecnologías!$F$2:$F$204,B10,Tecnologías!$G$2:$G$204,"Opcional") | G10: =SUMIFS(Tecnologías!$D$2:$D$204,Tecnologías!$F$2:$F$204,B10,Tecnologías!$G$2:$G$204,"Vertebral",Tecnologías!$C$2:$C$204,"<=4") | H10: =SUMIFS(Tecnologías!$D$2:$D$204,Tecnologías!$F$2:$F$204,B10,Tecnologías!$G$2:$G$204,"Vertebral") | I10: =AVERAGEIF(Tecnologías!$F$2:$F$204,B10,Tecnologías!$N$2:$N$204) | J10: =COUNTIFS(Tecnologías!$F$2:$F$204,B10,Tecnologías!$O$2:$O$204,"Alto")
B11: Sanidad y población | C11: Construcción | D11: =COUNTIF(Tecnologías!$F$2:$F$204,B11) | E11: =COUNTIFS(Tecnologías!$F$2:$F$204,B11,Tecnologías!$G$2:$G$204,"Vertebral") | F11: =COUNTIFS(Tecnologías!$F$2:$F$204,B11,Tecnologías!$G$2:$G$204,"Opcional") | G11: =SUMIFS(Tecnologías!$D$2:$D$204,Tecnologías!$F$2:$F$204,B11,Tecnologías!$G$2:$G$204,"Vertebral",Tecnologías!$C$2:$C$204,"<=4") | H11: =SUMIFS(Tecnologías!$D$2:$D$204,Tecnologías!$F$2:$F$204,B11,Tecnologías!$G$2:$G$204,"Vertebral") | I11: =AVERAGEIF(Tecnologías!$F$2:$F$204,B11,Tecnologías!$N$2:$N$204) | J11: =COUNTIFS(Tecnologías!$F$2:$F$204,B11,Tecnologías!$O$2:$O$204,"Alto")
B12: Diplomacia e imperio | C12: Civil | D12: =COUNTIF(Tecnologías!$F$2:$F$204,B12) | E12: =COUNTIFS(Tecnologías!$F$2:$F$204,B12,Tecnologías!$G$2:$G$204,"Vertebral") | F12: =COUNTIFS(Tecnologías!$F$2:$F$204,B12,Tecnologías!$G$2:$G$204,"Opcional") | G12: =SUMIFS(Tecnologías!$D$2:$D$204,Tecnologías!$F$2:$F$204,B12,Tecnologías!$G$2:$G$204,"Vertebral",Tecnologías!$C$2:$C$204,"<=4") | H12: =SUMIFS(Tecnologías!$D$2:$D$204,Tecnologías!$F$2:$F$204,B12,Tecnologías!$G$2:$G$204,"Vertebral") | I12: =AVERAGEIF(Tecnologías!$F$2:$F$204,B12,Tecnologías!$N$2:$N$204) | J12: =COUNTIFS(Tecnologías!$F$2:$F$204,B12,Tecnologías!$O$2:$O$204,"Alto")
B13: Armas y unidades | C13: Militar | D13: =COUNTIF(Tecnologías!$F$2:$F$204,B13) | E13: =COUNTIFS(Tecnologías!$F$2:$F$204,B13,Tecnologías!$G$2:$G$204,"Vertebral") | F13: =COUNTIFS(Tecnologías!$F$2:$F$204,B13,Tecnologías!$G$2:$G$204,"Opcional") | G13: =SUMIFS(Tecnologías!$D$2:$D$204,Tecnologías!$F$2:$F$204,B13,Tecnologías!$G$2:$G$204,"Vertebral",Tecnologías!$C$2:$C$204,"<=4") | H13: =SUMIFS(Tecnologías!$D$2:$D$204,Tecnologías!$F$2:$F$204,B13,Tecnologías!$G$2:$G$204,"Vertebral") | I13: =AVERAGEIF(Tecnologías!$F$2:$F$204,B13,Tecnologías!$N$2:$N$204) | J13: =COUNTIFS(Tecnologías!$F$2:$F$204,B13,Tecnologías!$O$2:$O$204,"Alto")
B14: Cuartel y entrenamiento | C14: Militar | D14: =COUNTIF(Tecnologías!$F$2:$F$204,B14) | E14: =COUNTIFS(Tecnologías!$F$2:$F$204,B14,Tecnologías!$G$2:$G$204,"Vertebral") | F14: =COUNTIFS(Tecnologías!$F$2:$F$204,B14,Tecnologías!$G$2:$G$204,"Opcional") | G14: =SUMIFS(Tecnologías!$D$2:$D$204,Tecnologías!$F$2:$F$204,B14,Tecnologías!$G$2:$G$204,"Vertebral",Tecnologías!$C$2:$C$204,"<=4") | H14: =SUMIFS(Tecnologías!$D$2:$D$204,Tecnologías!$F$2:$F$204,B14,Tecnologías!$G$2:$G$204,"Vertebral") | I14: =AVERAGEIF(Tecnologías!$F$2:$F$204,B14,Tecnologías!$N$2:$N$204) | J14: =COUNTIFS(Tecnologías!$F$2:$F$204,B14,Tecnologías!$O$2:$O$204,"Alto")
B15: Defensa | C15: Militar | D15: =COUNTIF(Tecnologías!$F$2:$F$204,B15) | E15: =COUNTIFS(Tecnologías!$F$2:$F$204,B15,Tecnologías!$G$2:$G$204,"Vertebral") | F15: =COUNTIFS(Tecnologías!$F$2:$F$204,B15,Tecnologías!$G$2:$G$204,"Opcional") | G15: =SUMIFS(Tecnologías!$D$2:$D$204,Tecnologías!$F$2:$F$204,B15,Tecnologías!$G$2:$G$204,"Vertebral",Tecnologías!$C$2:$C$204,"<=4") | H15: =SUMIFS(Tecnologías!$D$2:$D$204,Tecnologías!$F$2:$F$204,B15,Tecnologías!$G$2:$G$204,"Vertebral") | I15: =AVERAGEIF(Tecnologías!$F$2:$F$204,B15,Tecnologías!$N$2:$N$204) | J15: =COUNTIFS(Tecnologías!$F$2:$F$204,B15,Tecnologías!$O$2:$O$204,"Alto")
B16: Guerra y conquista | C16: Militar | D16: =COUNTIF(Tecnologías!$F$2:$F$204,B16) | E16: =COUNTIFS(Tecnologías!$F$2:$F$204,B16,Tecnologías!$G$2:$G$204,"Vertebral") | F16: =COUNTIFS(Tecnologías!$F$2:$F$204,B16,Tecnologías!$G$2:$G$204,"Opcional") | G16: =SUMIFS(Tecnologías!$D$2:$D$204,Tecnologías!$F$2:$F$204,B16,Tecnologías!$G$2:$G$204,"Vertebral",Tecnologías!$C$2:$C$204,"<=4") | H16: =SUMIFS(Tecnologías!$D$2:$D$204,Tecnologías!$F$2:$F$204,B16,Tecnologías!$G$2:$G$204,"Vertebral") | I16: =AVERAGEIF(Tecnologías!$F$2:$F$204,B16,Tecnologías!$N$2:$N$204) | J16: =COUNTIFS(Tecnologías!$F$2:$F$204,B16,Tecnologías!$O$2:$O$204,"Alto")
B17: Total | D17: =SUM(D5:D16) | E17: =SUM(E5:E16) | F17: =SUM(F5:F16) | G17: =SUM(G5:G16) | H17: =SUM(H5:H16) | J17: =SUM(J5:J16)

Sheet Resumen
B1: Resumen del árbol
B3: Tecnologías por nivel y tipo
B4: Nivel | C4: Civil | D4: Construcción | E4: Militar | F4: Total | G4: Costo c/u | H4: Costo total
B5: 1 | C5: =COUNTIFS(Tecnologías!$C$2:$C$204,$B5,Tecnologías!$E$2:$E$204,"Civil") | D5: =COUNTIFS(Tecnologías!$C$2:$C$204,$B5,Tecnologías!$E$2:$E$204,"Construcción") | E5: =COUNTIFS(Tecnologías!$C$2:$C$204,$B5,Tecnologías!$E$2:$E$204,"Militar") | F5: =SUM(C5:E5) | G5: =B5*Reglas!$C$5 | H5: =F5*G5
B6: 2 | C6: =COUNTIFS(Tecnologías!$C$2:$C$204,$B6,Tecnologías!$E$2:$E$204,"Civil") | D6: =COUNTIFS(Tecnologías!$C$2:$C$204,$B6,Tecnologías!$E$2:$E$204,"Construcción") | E6: =COUNTIFS(Tecnologías!$C$2:$C$204,$B6,Tecnologías!$E$2:$E$204,"Militar") | F6: =SUM(C6:E6) | G6: =B6*Reglas!$C$5 | H6: =F6*G6
B7: 3 | C7: =COUNTIFS(Tecnologías!$C$2:$C$204,$B7,Tecnologías!$E$2:$E$204,"Civil") | D7: =COUNTIFS(Tecnologías!$C$2:$C$204,$B7,Tecnologías!$E$2:$E$204,"Construcción") | E7: =COUNTIFS(Tecnologías!$C$2:$C$204,$B7,Tecnologías!$E$2:$E$204,"Militar") | F7: =SUM(C7:E7) | G7: =B7*Reglas!$C$5 | H7: =F7*G7
B8: 4 | C8: =COUNTIFS(Tecnologías!$C$2:$C$204,$B8,Tecnologías!$E$2:$E$204,"Civil") | D8: =COUNTIFS(Tecnologías!$C$2:$C$204,$B8,Tecnologías!$E$2:$E$204,"Construcción") | E8: =COUNTIFS(Tecnologías!$C$2:$C$204,$B8,Tecnologías!$E$2:$E$204,"Militar") | F8: =SUM(C8:E8) | G8: =B8*Reglas!$C$5 | H8: =F8*G8
B9: 5 | C9: =COUNTIFS(Tecnologías!$C$2:$C$204,$B9,Tecnologías!$E$2:$E$204,"Civil") | D9: =COUNTIFS(Tecnologías!$C$2:$C$204,$B9,Tecnologías!$E$2:$E$204,"Construcción") | E9: =COUNTIFS(Tecnologías!$C$2:$C$204,$B9,Tecnologías!$E$2:$E$204,"Militar") | F9: =SUM(C9:E9) | G9: =B9*Reglas!$C$5 | H9: =F9*G9
B10: Total | C10: =SUM(C5:C9) | D10: =SUM(D5:D9) | E10: =SUM(E5:E9) | F10: =SUM(F5:F9) | H10: =SUM(H5:H9)
B12: Origen y valoración
B13: Origen | C13: Cantidad | D13: Valoración media
B14: Tuya | C14: =COUNTIF(Tecnologías!$M$2:$M$204,B14) | D14: =AVERAGEIF(Tecnologías!$M$2:$M$204,B14,Tecnologías!$N$2:$N$204)
B15: Mía | C15: =COUNTIF(Tecnologías!$M$2:$M$204,B15) | D15: =AVERAGEIF(Tecnologías!$M$2:$M$204,B15,Tecnologías!$N$2:$N$204)
B16: Todas | C16: =SUM(C14:C15) | D16: =AVERAGE(Tecnologías!$N$2:$N$204)
B18: Riesgo de balance
B19: Riesgo | C19: Cantidad
B20: Alto | C20: =COUNTIF(Tecnologías!$O$2:$O$204,B20)
B21: Medio | C21: =COUNTIF(Tecnologías!$O$2:$O$204,B21)
B22: Bajo | C22: =COUNTIF(Tecnologías!$O$2:$O$204,B22)
B24: Columna vertebral y opcionales
B25: Columna | C25: Cantidad | D25: Costo total
B26: Vertebral | C26: =COUNTIF(Tecnologías!$G$2:$G$204,B26) | D26: =SUMIF(Tecnologías!$G$2:$G$204,B26,Tecnologías!$D$2:$D$204)
B27: Opcional | C27: =COUNTIF(Tecnologías!$G$2:$G$204,B27) | D27: =SUMIF(Tecnologías!$G$2:$G$204,B27,Tecnologías!$D$2:$D$204)
